*** Starting uWSGI 2.0.15 (64bit) on [Sat Dec  2 17:30:55 2017] ***
compiled with version: 5.4.0 20160609 on 09 November 2017 14:32:58
os: Linux-4.4.0-87-generic #110-Ubuntu SMP Tue Jul 18 12:55:35 UTC 2017
nodename: iZ23x5e5nbxZ
machine: x86_64
clock source: unix
detected number of CPU cores: 2
current working directory: /home/caolei
detected binary path: /usr/local/bin/uwsgi
!!! no internal routing support, rebuild with pcre support !!!
uWSGI running as root, you can use --uid/--gid/--chroot options
*** WARNING: you are running uWSGI as root !!! (use the --uid flag) *** 
*** WARNING: you are running uWSGI without its master process manager ***
your processes number limit is 15657
your memory page size is 4096 bytes
detected max file descriptor number: 65535
lock engine: pthread robust mutexes
thunder lock: disabled (you can enable it with --thunder-lock)
uwsgi socket 0 bound to TCP address 127.0.0.1:8848 fd 3
Python version: 3.5.2 (default, Nov 17 2016, 17:05:23)  [GCC 5.4.0 20160609]
*** Python threads support is disabled. You can enable it with --enable-threads ***
Python main interpreter initialized at 0x20b5930
your server socket listen backlog is limited to 100 connections
your mercy for graceful operations on workers is 60 seconds
mapped 72768 bytes (71 KB) for 1 cores
*** Operational MODE: single process ***
Traceback (most recent call last):
  File "/home/caolei/flask/app.py", line 5, in <module>
    from model import User
ImportError: No module named 'model'
unable to load app 0 (mountpoint='') (callable not found or import error)
*** no app loaded. going in full dynamic mode ***
*** uWSGI is running in multiple interpreter mode ***
spawned uWSGI worker 1 (and the only) (pid: 16390, cores: 1)
ImportError: No module named 'app'
unable to load app 0 (mountpoint='') (callable not found or import error)
--- no python application found, check your startup logs for errors ---
[pid: 16390|app: -1|req: -1/1] 166.111.69.75 () {44 vars in 727 bytes} [Sat Dec  2 17:31:25 2017] GET / => generated 21 bytes in 0 msecs (HTTP/1.1 500) 2 headers in 83 bytes (0 switches on core 0)
*** Starting uWSGI 2.0.15 (64bit) on [Sat Dec  2 17:31:35 2017] ***
compiled with version: 5.4.0 20160609 on 09 November 2017 14:32:58
os: Linux-4.4.0-87-generic #110-Ubuntu SMP Tue Jul 18 12:55:35 UTC 2017
nodename: iZ23x5e5nbxZ
machine: x86_64
clock source: unix
detected number of CPU cores: 2
current working directory: /home/caolei
detected binary path: /usr/local/bin/uwsgi
!!! no internal routing support, rebuild with pcre support !!!
uWSGI running as root, you can use --uid/--gid/--chroot options
*** WARNING: you are running uWSGI as root !!! (use the --uid flag) *** 
*** WARNING: you are running uWSGI without its master process manager ***
your processes number limit is 15657
your memory page size is 4096 bytes
detected max file descriptor number: 65535
lock engine: pthread robust mutexes
thunder lock: disabled (you can enable it with --thunder-lock)
probably another instance of uWSGI is running on the same address (127.0.0.1:8848).
bind(): Address already in use [core/socket.c line 769]
*** Starting uWSGI 2.0.15 (64bit) on [Sat Dec  2 17:37:45 2017] ***
compiled with version: 5.4.0 20160609 on 09 November 2017 14:32:58
os: Linux-4.4.0-87-generic #110-Ubuntu SMP Tue Jul 18 12:55:35 UTC 2017
nodename: iZ23x5e5nbxZ
machine: x86_64
clock source: unix
detected number of CPU cores: 2
current working directory: /home/caolei/flask
detected binary path: /usr/local/bin/uwsgi
!!! no internal routing support, rebuild with pcre support !!!
uWSGI running as root, you can use --uid/--gid/--chroot options
*** WARNING: you are running uWSGI as root !!! (use the --uid flag) *** 
*** WARNING: you are running uWSGI without its master process manager ***
your processes number limit is 15657
your memory page size is 4096 bytes
detected max file descriptor number: 65535
lock engine: pthread robust mutexes
thunder lock: disabled (you can enable it with --thunder-lock)
uwsgi socket 0 bound to TCP address 127.0.0.1:8848 fd 3
Python version: 3.5.2 (default, Nov 17 2016, 17:05:23)  [GCC 5.4.0 20160609]
*** Python threads support is disabled. You can enable it with --enable-threads ***
Python main interpreter initialized at 0x11ff930
your server socket listen backlog is limited to 100 connections
your mercy for graceful operations on workers is 60 seconds
mapped 72768 bytes (71 KB) for 1 cores
*** Operational MODE: single process ***
WSGI app 0 (mountpoint='') ready in 1 seconds on interpreter 0x11ff930 pid: 16629 (default app)
*** uWSGI is running in multiple interpreter mode ***
spawned uWSGI worker 1 (and the only) (pid: 16629, cores: 1)
[2017-12-02 17:37:57,919] ERROR in app: Exception on /login [GET]
Traceback (most recent call last):
  File "/usr/local/lib/python3.5/dist-packages/flask/app.py", line 1982, in wsgi_app
    response = self.full_dispatch_request()
  File "/usr/local/lib/python3.5/dist-packages/flask/app.py", line 1614, in full_dispatch_request
    rv = self.handle_user_exception(e)
  File "/usr/local/lib/python3.5/dist-packages/flask/app.py", line 1517, in handle_user_exception
    reraise(exc_type, exc_value, tb)
  File "/usr/local/lib/python3.5/dist-packages/flask/_compat.py", line 33, in reraise
    raise value
  File "/usr/local/lib/python3.5/dist-packages/flask/app.py", line 1612, in full_dispatch_request
    rv = self.dispatch_request()
  File "/usr/local/lib/python3.5/dist-packages/flask/app.py", line 1598, in dispatch_request
    return self.view_functions[rule.endpoint](**req.view_args)
  File "/home/caolei/flask/app.py", line 36, in login
    xjson=json.loads(dict_data['body'])
KeyError: 'body'
[pid: 16629|app: 0|req: 1/1] 166.111.69.75 () {46 vars in 768 bytes} [Sat Dec  2 17:37:57 2017] GET /login => generated 291 bytes in 3 msecs (HTTP/1.1 500) 2 headers in 84 bytes (1 switches on core 0)
[2017-12-02 17:38:00,759] ERROR in app: Exception on /login [GET]
Traceback (most recent call last):
  File "/usr/local/lib/python3.5/dist-packages/flask/app.py", line 1982, in wsgi_app
    response = self.full_dispatch_request()
  File "/usr/local/lib/python3.5/dist-packages/flask/app.py", line 1614, in full_dispatch_request
    rv = self.handle_user_exception(e)
  File "/usr/local/lib/python3.5/dist-packages/flask/app.py", line 1517, in handle_user_exception
    reraise(exc_type, exc_value, tb)
  File "/usr/local/lib/python3.5/dist-packages/flask/_compat.py", line 33, in reraise
    raise value
  File "/usr/local/lib/python3.5/dist-packages/flask/app.py", line 1612, in full_dispatch_request
    rv = self.dispatch_request()
  File "/usr/local/lib/python3.5/dist-packages/flask/app.py", line 1598, in dispatch_request
    return self.view_functions[rule.endpoint](**req.view_args)
  File "/home/caolei/flask/app.py", line 36, in login
    xjson=json.loads(dict_data['body'])
KeyError: 'body'
[pid: 16629|app: 0|req: 2/2] 166.111.69.75 () {46 vars in 768 bytes} [Sat Dec  2 17:38:00 2017] GET /login => generated 291 bytes in 1 msecs (HTTP/1.1 500) 2 headers in 84 bytes (1 switches on core 0)
[pid: 16629|app: 0|req: 3/3] 166.111.69.75 () {44 vars in 727 bytes} [Sat Dec  2 17:38:03 2017] GET / => generated 18 bytes in 0 msecs (HTTP/1.1 200) 2 headers in 79 bytes (1 switches on core 0)
